{"errorMessage": "An error occurred (BadRequestException) when calling the PostToConnection operation: Invalid connectionId: test-connection-id-1234", "errorType": "ClientError", "requestId": "de192447-4899-4a9e-947a-95431378ac6d", "stackTrace": ["  File \"/var/task/index.py\", line 24, in lambda_handler\n    apigw_client.post_to_connection(ConnectionId=connectionId, Data=message.encode('utf-8'))\n", "  File \"/var/runtime/botocore/client.py\", line 569, in _api_call\n    return self._make_api_call(operation_name, kwargs)\n", "  File \"/var/runtime/botocore/client.py\", line 1023, in _make_api_call\n    raise error_class(parsed_response, operation_name)\n"]}